Workbook

Sheet Predict
A1: 4D manual formula: top 5 numbers for a draw date
A3: Draw date | B3: 46313 | C3: =IFERROR(INDEX(Calendar!$B$2:$B$441,MATCH($B$3,Calendar!$A$2:$A$441,0)),"date not in Calendar") -> Sun | E3: Yellow cell = the only input. Everything else is calculated.
A5: Step 1: the date's parameters | P5: RESULT: top 5 numbers
A6: Parameter | B6: Value on this date | C6: Lookup key | P6: Rank | Q6: Number | R6: Points
A7: Chinese year yin/yang | B7: =IFERROR(INDEX(Calendar!$C$2:$C$441,MATCH($B$3,Calendar!$A$2:$A$441,0)),"") -> Yang | C7: ="year_yinyang|"&B7 -> year_yinyang|Yang | P7: 1 | Q7: =INDEX($F$33:$F$48,MATCH(LARGE($G$33:$G$48,1),$G$33:$G$48,0)) -> 9509 | R7: =LARGE($G$33:$G$48,1) -> 3
A8: Venus combust (Vedic) | B8: =IFERROR(INDEX(Calendar!$D$2:$D$441,MATCH($B$3,Calendar!$A$2:$A$441,0)),"") -> True | C8: ="venus_combust|"&B8 -> venus_combust|True | P8: 2 | Q8: =INDEX($F$33:$F$48,MATCH(LARGE($G$33:$G$48,2),$G$33:$G$48,0)) -> 9507 | R8: =LARGE($G$33:$G$48,2) -> 3
A9: Jupiter combust (Vedic) | B9: =IFERROR(INDEX(Calendar!$E$2:$E$441,MATCH($B$3,Calendar!$A$2:$A$441,0)),"") -> False | C9: ="jupiter_combust|"&B9 -> jupiter_combust|False | P9: 3 | Q9: =INDEX($F$33:$F$48,MATCH(LARGE($G$33:$G$48,3),$G$33:$G$48,0)) -> 9599 | R9: =LARGE($G$33:$G$48,3) -> 2
A10: Masa, lunar month (Vedic) | B10: =IFERROR(INDEX(Calendar!$F$2:$F$441,MATCH($B$3,Calendar!$A$2:$A$441,0)),"") -> Ashvin | C10: ="masa|"&B10 -> masa|Ashvin | P10: 4 | Q10: =INDEX($F$33:$F$48,MATCH(LARGE($G$33:$G$48,4),$G$33:$G$48,0)) -> 9909 | R10: =LARGE($G$33:$G$48,4) -> 2
A11: Chinese year heavenly stem | B11: =IFERROR(INDEX(Calendar!$G$2:$G$441,MATCH($B$3,Calendar!$A$2:$A$441,0)),"") -> Bing | C11: ="year_stem|"&B11 -> year_stem|Bing | P11: 5 | Q11: =INDEX($F$33:$F$48,MATCH(LARGE($G$33:$G$48,5),$G$33:$G$48,0)) -> 8509 | R11: =LARGE($G$33:$G$48,5) -> 2
A12: Chinese lunar day | B12: =IFERROR(INDEX(Calendar!$H$2:$H$441,MATCH($B$3,Calendar!$A$2:$A$441,0)),"") -> 9 | C12: ="lunar_day|"&B12 -> lunar_day|9
P13: Same numbers for Magnum, Sports Toto and Da Ma Cai (the tables pool all three).
P14: Not a guarantee: see the 'How to use' sheet for the tested hit rate.
A15: Step 2: points from each parameter's table (position 1-4, digit 0-9)
D16: P1 0 | E16: P1 1 | F16: P1 2 | G16: P1 3 | H16: P1 4 | I16: P1 5 | J16: P1 6 | K16: P1 7 | L16: P1 8 | M16: P1 9 | N16: P2 0 | O16: P2 1 | P16: P2 2 | Q16: P2 3 | R16: P2 4 | S16: P2 5 | T16: P2 6 | U16: P2 7 | V16: P2 8 | W16: P2 9 | X16: P3 0 | Y16: P3 1 | Z16: P3 2 | AA16: P3 3 | AB16: P3 4 | AC16: P3 5 | AD16: P3 6 | AE16: P3 7 | AF16: P3 8 | AG16: P3 9 | AH16: P4 0 | AI16: P4 1 | AJ16: P4 2 | AK16: P4 3 | AL16: P4 4 | AM16: P4 5 | AN16: P4 6 | AO16: P4 7 | AP16: P4 8 | AQ16: P4 9
A17: Chinese year yin/yang | D17: =IFERROR(INDEX(Tables!$D$2:$D$59,MATCH($C$7,Tables!$C$2:$C$59,0)),0) -> 0 | E17: =IFERROR(INDEX(Tables!$E$2:$E$59,MATCH($C$7,Tables!$C$2:$C$59,0)),0) -> 0 | F17: =IFERROR(INDEX(Tables!$F$2:$F$59,MATCH($C$7,Tables!$C$2:$C$59,0)),0) -> 0 | G17: =IFERROR(INDEX(Tables!$G$2:$G$59,MATCH($C$7,Tables!$C$2:$C$59,0)),0) -> 0 | H17: =IFERROR(INDEX(Tables!$H$2:$H$59,MATCH($C$7,Tables!$C$2:$C$59,0)),0) -> 0 | I17: =IFERROR(INDEX(Tables!$I$2:$I$59,MATCH($C$7,Tables!$C$2:$C$59,0)),0) -> 0 | J17: =IFERROR(INDEX(Tables!$J$2:$J$59,MATCH($C$7,Tables!$C$2:$C$59,0)),0) -> 0 | K17: =IFERROR(INDEX(Tables!$K$2:$K$59,MATCH($C$7,Tables!$C$2:$C$59,0)),0) -> 0 | L17: =IFERROR(INDEX(Tables!$L$2:$L$59,MATCH($C$7,Tables!$C$2:$C$59,0)),0) -> 0 | M17: =IFERROR(INDEX(Tables!$M$2:$M$59,MATCH($C$7,Tables!$C$2:$C$59,0)),0) -> 0 | N17: =IFERROR(INDEX(Tables!$N$2:$N$59,MATCH($C$7,Tables!$C$2:$C$59,0)),0) -> 0 | O17: =IFERROR(INDEX(Tables!$O$2:$O$59,MATCH($C$7,Tables!$C$2:$C$59,0)),0) -> 0 | P17: =IFERROR(INDEX(Tables!$P$2:$P$59,MATCH($C$7,Tables!$C$2:$C$59,0)),0) -> 0 | Q17: =IFERROR(INDEX(Tables!$Q$2:$Q$59,MATCH($C$7,Tables!$C$2:$C$59,0)),0) -> 0 | R17: =IFERROR(INDEX(Tables!$R$2:$R$59,MATCH($C$7,Tables!$C$2:$C$59,0)),0) -> 0 | S17: =IFERROR(INDEX(Tables!$S$2:$S$59,MATCH($C$7,Tables!$C$2:$C$59,0)),0) -> 0 | T17: =IFERROR(INDEX(Tables!$T$2:$T$59,MATCH($C$7,Tables!$C$2:$C$59,0)),0) -> 0 | U17: =IFERROR(INDEX(Tables!$U$2:$U$59,MATCH($C$7,Tables!$C$2:$C$59,0)),0) -> 0 | V17: =IFERROR(INDEX(Tables!$V$2:$V$59,MATCH($C$7,Tables!$C$2:$C$59,0)),0) -> 0 | W17: =IFERROR(INDEX(Tables!$W$2:$W$59,MATCH($C$7,Tables!$C$2:$C$59,0)),0) -> 0 | X17: =IFERROR(INDEX(Tables!$X$2:$X$59,MATCH($C$7,Tables!$C$2:$C$59,0)),0) -> 0 | Y17: =IFERROR(INDEX(Tables!$Y$2:$Y$59,MATCH($C$7,Tables!$C$2:$C$59,0)),0) -> 0 | Z17: =IFERROR(INDEX(Tables!$Z$2:$Z$59,MATCH($C$7,Tables!$C$2:$C$59,0)),0) -> 0 | AA17: =IFERROR(INDEX(Tables!$AA$2:$AA$59,MATCH($C$7,Tables!$C$2:$C$59,0)),0) -> 0 | AB17: =IFERROR(INDEX(Tables!$AB$2:$AB$59,MATCH($C$7,Tables!$C$2:$C$59,0)),0) -> 0 | AC17: =IFERROR(INDEX(Tables!$AC$2:$AC$59,MATCH($C$7,Tables!$C$2:$C$59,0)),0) -> 0 | AD17: =IFERROR(INDEX(Tables!$AD$2:$AD$59,MATCH($C$7,Tables!$C$2:$C$59,0)),0) -> 0 | AE17: =IFERROR(INDEX(Tables!$AE$2:$AE$59,MATCH($C$7,Tables!$C$2:$C$59,0)),0) -> 0 | AF17: =IFERROR(INDEX(Tables!$AF$2:$AF$59,MATCH($C$7,Tables!$C$2:$C$59,0)),0) -> 0 | AG17: =IFERROR(INDEX(Tables!$AG$2:$AG$59,MATCH($C$7,Tables!$C$2:$C$59,0)),0) -> 0 | AH17: =IFERROR(INDEX(Tables!$AH$2:$AH$59,MATCH($C$7,Tables!$C$2:$C$59,0)),0) -> 0 | AI17: =IFERROR(INDEX(Tables!$AI$2:$AI$59,MATCH($C$7,Tables!$C$2:$C$59,0)),0) -> 0 | AJ17: =IFERROR(INDEX(Tables!$AJ$2:$AJ$59,MATCH($C$7,Tables!$C$2:$C$59,0)),0) -> 0 | AK17: =IFERROR(INDEX(Tables!$AK$2:$AK$59,MATCH($C$7,Tables!$C$2:$C$59,0)),0) -> 0 | AL17: =IFERROR(INDEX(Tables!$AL$2:$AL$59,MATCH($C$7,Tables!$C$2:$C$59,0)),0) -> 0 | AM17: =IFERROR(INDEX(Tables!$AM$2:$AM$59,MATCH($C$7,Tables!$C$2:$C$59,0)),0) -> 0 | AN17: =IFERROR(INDEX(Tables!$AN$2:$AN$59,MATCH($C$7,Tables!$C$2:$C$59,0)),0) -> 0 | AO17: =IFERROR(INDEX(Tables!$AO$2:$AO$59,MATCH($C$7,Tables!$C$2:$C$59,0)),0) -> 0 | AP17: =IFERROR(INDEX(Tables!$AP$2:$AP$59,MATCH($C$7,Tables!$C$2:$C$59,0)),0) -> 0 | AQ17: =IFERROR(INDEX(Tables!$AQ$2:$AQ$59,MATCH($C$7,Tables!$C$2:$C$59,0)),0) -> 0
A18: Venus combust (Vedic) | D18: =IFERROR(INDEX(Tables!$D$2:$D$59,MATCH($C$8,Tables!$C$2:$C$59,0)),0) -> 0 | E18: =IFERROR(INDEX(Tables!$E$2:$E$59,MATCH($C$8,Tables!$C$2:$C$59,0)),0) -> -1 | F18: =IFERROR(INDEX(Tables!$F$2:$F$59,MATCH($C$8,Tables!$C$2:$C$59,0)),0) -> 0 | G18: =IFERROR(INDEX(Tables!$G$2:$G$59,MATCH($C$8,Tables!$C$2:$C$59,0)),0) -> 0 | H18: =IFERROR(INDEX(Tables!$H$2:$H$59,MATCH($C$8,Tables!$C$2:$C$59,0)),0) -> 0 | I18: =IFERROR(INDEX(Tables!$I$2:$I$59,MATCH($C$8,Tables!$C$2:$C$59,0)),0) -> 0 | J18: =IFERROR(INDEX(Tables!$J$2:$J$59,MATCH($C$8,Tables!$C$2:$C$59,0)),0) -> 0 | K18: =IFERROR(INDEX(Tables!$K$2:$K$59,MATCH($C$8,Tables!$C$2:$C$59,0)),0) -> 0 | L18: =IFERROR(INDEX(Tables!$L$2:$L$59,MATCH($C$8,Tables!$C$2:$C$59,0)),0) -> 0 | M18: =IFERROR(INDEX(Tables!$M$2:$M$59,MATCH($C$8,Tables!$C$2:$C$59,0)),0) -> 1 | N18: =IFERROR(INDEX(Tables!$N$2:$N$59,MATCH($C$8,Tables!$C$2:$C$59,0)),0) -> 0 | O18: =IFERROR(INDEX(Tables!$O$2:$O$59,MATCH($C$8,Tables!$C$2:$C$59,0)),0) -> 0 | P18: =IFERROR(INDEX(Tables!$P$2:$P$59,MATCH($C$8,Tables!$C$2:$C$59,0)),0) -> 0 | Q18: =IFERROR(INDEX(Tables!$Q$2:$Q$59,MATCH($C$8,Tables!$C$2:$C$59,0)),0) -> 0 | R18: =IFERROR(INDEX(Tables!$R$2:$R$59,MATCH($C$8,Tables!$C$2:$C$59,0)),0) -> 0 | S18: =IFERROR(INDEX(Tables!$S$2:$S$59,MATCH($C$8,Tables!$C$2:$C$59,0)),0) -> 1 | T18: =IFERROR(INDEX(Tables!$T$2:$T$59,MATCH($C$8,Tables!$C$2:$C$59,0)),0) -> 0 | U18: =IFERROR(INDEX(Tables!$U$2:$U$59,MATCH($C$8,Tables!$C$2:$C$59,0)),0) -> 0 | V18: =IFERROR(INDEX(Tables!$V$2:$V$59,MATCH($C$8,Tables!$C$2:$C$59,0)),0) -> 0 | W18: =IFERROR(INDEX(Tables!$W$2:$W$59,MATCH($C$8,Tables!$C$2:$C$59,0)),0) -> 0 | X18: =IFERROR(INDEX(Tables!$X$2:$X$59,MATCH($C$8,Tables!$C$2:$C$59,0)),0) -> 1 | Y18: =IFERROR(INDEX(Tables!$Y$2:$Y$59,MATCH($C$8,Tables!$C$2:$C$59,0)),0) -> 0 | Z18: =IFERROR(INDEX(Tables!$Z$2:$Z$59,MATCH($C$8,Tables!$C$2:$C$59,0)),0) -> 0 | AA18: =IFERROR(INDEX(Tables!$AA$2:$AA$59,MATCH($C$8,Tables!$C$2:$C$59,0)),0) -> 0 | AB18: =IFERROR(INDEX(Tables!$AB$2:$AB$59,MATCH($C$8,Tables!$C$2:$C$59,0)),0) -> 0 | AC18: =IFERROR(INDEX(Tables!$AC$2:$AC$59,MATCH($C$8,Tables!$C$2:$C$59,0)),0) -> 0 | AD18: =IFERROR(INDEX(Tables!$AD$2:$AD$59,MATCH($C$8,Tables!$C$2:$C$59,0)),0) -> 0 | AE18: =IFERROR(INDEX(Tables!$AE$2:$AE$59,MATCH($C$8,Tables!$C$2:$C$59,0)),0) -> 0 | AF18: =IFERROR(INDEX(Tables!$AF$2:$AF$59,MATCH($C$8,Tables!$C$2:$C$59,0)),0) -> 0 | AG18: =IFERROR(INDEX(Tables!$AG$2:$AG$59,MATCH($C$8,Tables!$C$2:$C$59,0)),0) -> 0 | AH18: =IFERROR(INDEX(Tables!$AH$2:$AH$59,MATCH($C$8,Tables!$C$2:$C$59,0)),0) -> 0 | AI18: =IFERROR(INDEX(Tables!$AI$2:$AI$59,MATCH($C$8,Tables!$C$2:$C$59,0)),0) -> 0 | AJ18: =IFERROR(INDEX(Tables!$AJ$2:$AJ$59,MATCH($C$8,Tables!$C$2:$C$59,0)),0) -> 0 | AK18: =IFERROR(INDEX(Tables!$AK$2:$AK$59,MATCH($C$8,Tables!$C$2:$C$59,0)),0) -> 0 | AL18: =IFERROR(INDEX(Tables!$AL$2:$AL$59,MATCH($C$8,Tables!$C$2:$C$59,0)),0) -> 0 | AM18: =IFERROR(INDEX(Tables!$AM$2:$AM$59,MATCH($C$8,Tables!$C$2:$C$59,0)),0) -> 0 | AN18: =IFERROR(INDEX(Tables!$AN$2:$AN$59,MATCH($C$8,Tables!$C$2:$C$59,0)),0) -> 0 | AO18: =IFERROR(INDEX(Tables!$AO$2:$AO$59,MATCH($C$8,Tables!$C$2:$C$59,0)),0) -> 0 | AP18: =IFERROR(INDEX(Tables!$AP$2:$AP$59,MATCH($C$8,Tables!$C$2:$C$59,0)),0) -> -1 | AQ18: =IFERROR(INDEX(Tables!$AQ$2:$AQ$59,MATCH($C$8,Tables!$C$2:$C$59,0)),0) -> 0
A19: Jupiter combust (Vedic) | D19: =IFERROR(INDEX(Tables!$D$2:$D$59,MATCH($C$9,Tables!$C$2:$C$59,0)),0) -> 0 | E19: =IFERROR(INDEX(Tables!$E$2:$E$59,MATCH($C$9,Tables!$C$2:$C$59,0)),0) -> 0 | F19: =IFERROR(INDEX(Tables!$F$2:$F$59,MATCH($C$9,Tables!$C$2:$C$59,0)),0) -> 0 | G19: =IFERROR(INDEX(Tables!$G$2:$G$59,MATCH($C$9,Tables!$C$2:$C$59,0)),0) -> 0 | H19: =IFERROR(INDEX(Tables!$H$2:$H$59,MATCH($C$9,Tables!$C$2:$C$59,0)),0) -> 0 | I19: =IFERROR(INDEX(Tables!$I$2:$I$59,MATCH($C$9,Tables!$C$2:$C$59,0)),0) -> 0 | J19: =IFERROR(INDEX(Tables!$J$2:$J$59,MATCH($C$9,Tables!$C$2:$C$59,0)),0) -> 0 | K19: =IFERROR(INDEX(Tables!$K$2:$K$59,MATCH($C$9,Tables!$C$2:$C$59,0)),0) -> 0 | L19: =IFERROR(INDEX(Tables!$L$2:$L$59,MATCH($C$9,Tables!$C$2:$C$59,0)),0) -> 0 | M19: =IFERROR(INDEX(Tables!$M$2:$M$59,MATCH($C$9,Tables!$C$2:$C$59,0)),0) -> 0 | N19: =IFERROR(INDEX(Tables!$N$2:$N$59,MATCH($C$9,Tables!$C$2:$C$59,0)),0) -> 0 | O19: =IFERROR(INDEX(Tables!$O$2:$O$59,MATCH($C$9,Tables!$C$2:$C$59,0)),0) -> 0 | P19: =IFERROR(INDEX(Tables!$P$2:$P$59,MATCH($C$9,Tables!$C$2:$C$59,0)),0) -> 0 | Q19: =IFERROR(INDEX(Tables!$Q$2:$Q$59,MATCH($C$9,Tables!$C$2:$C$59,0)),0) -> 0 | R19: =IFERROR(INDEX(Tables!$R$2:$R$59,MATCH($C$9,Tables!$C$2:$C$59,0)),0) -> 0 | S19: =IFERROR(INDEX(Tables!$S$2:$S$59,MATCH($C$9,Tables!$C$2:$C$59,0)),0) -> 0 | T19: =IFERROR(INDEX(Tables!$T$2:$T$59,MATCH($C$9,Tables!$C$2:$C$59,0)),0) -> 0 | U19: =IFERROR(INDEX(Tables!$U$2:$U$59,MATCH($C$9,Tables!$C$2:$C$59,0)),0) -> 0 | V19: =IFERROR(INDEX(Tables!$V$2:$V$59,MATCH($C$9,Tables!$C$2:$C$59,0)),0) -> 0 | W19: =IFERROR(INDEX(Tables!$W$2:$W$59,MATCH($C$9,Tables!$C$2:$C$59,0)),0) -> 0 | X19: =IFERROR(INDEX(Tables!$X$2:$X$59,MATCH($C$9,Tables!$C$2:$C$59,0)),0) -> 0 | Y19: =IFERROR(INDEX(Tables!$Y$2:$Y$59,MATCH($C$9,Tables!$C$2:$C$59,0)),0) -> 0 | Z19: =IFERROR(INDEX(Tables!$Z$2:$Z$59,MATCH($C$9,Tables!$C$2:$C$59,0)),0) -> 0 | AA19: =IFERROR(INDEX(Tables!$AA$2:$AA$59,MATCH($C$9,Tables!$C$2:$C$59,0)),0) -> 0 | AB19: =IFERROR(INDEX(Tables!$AB$2:$AB$59,MATCH($C$9,Tables!$C$2:$C$59,0)),0) -> 0 | AC19: =IFERROR(INDEX(Tables!$AC$2:$AC$59,MATCH($C$9,Tables!$C$2:$C$59,0)),0) -> 0 | AD19: =IFERROR(INDEX(Tables!$AD$2:$AD$59,MATCH($C$9,Tables!$C$2:$C$59,0)),0) -> 0 | AE19: =IFERROR(INDEX(Tables!$AE$2:$AE$59,MATCH($C$9,Tables!$C$2:$C$59,0)),0) -> 0 | AF19: =IFERROR(INDEX(Tables!$AF$2:$AF$59,MATCH($C$9,Tables!$C$2:$C$59,0)),0) -> 0 | AG19: =IFERROR(INDEX(Tables!$AG$2:$AG$59,MATCH($C$9,Tables!$C$2:$C$59,0)),0) -> 0 | AH19: =IFERROR(INDEX(Tables!$AH$2:$AH$59,MATCH($C$9,Tables!$C$2:$C$59,0)),0) -> 0 | AI19: =IFERROR(INDEX(Tables!$AI$2:$AI$59,MATCH($C$9,Tables!$C$2:$C$59,0)),0) -> 0 | AJ19: =IFERROR(INDEX(Tables!$AJ$2:$AJ$59,MATCH($C$9,Tables!$C$2:$C$59,0)),0) -> 0 | AK19: =IFERROR(INDEX(Tables!$AK$2:$AK$59,MATCH($C$9,Tables!$C$2:$C$59,0)),0) -> 0 | AL19: =IFERROR(INDEX(Tables!$AL$2:$AL$59,MATCH($C$9,Tables!$C$2:$C$59,0)),0) -> 0 | AM19: =IFERROR(INDEX(Tables!$AM$2:$AM$59,MATCH($C$9,Tables!$C$2:$C$59,0)),0) -> 0 | AN19: =IFERROR(INDEX(Tables!$AN$2:$AN$59,MATCH($C$9,Tables!$C$2:$C$59,0)),0) -> 0 | AO19: =IFERROR(INDEX(Tables!$AO$2:$AO$59,MATCH($C$9,Tables!$C$2:$C$59,0)),0) -> 0 | AP19: =IFERROR(INDEX(Tables!$AP$2:$AP$59,MATCH($C$9,Tables!$C$2:$C$59,0)),0) -> 0 | AQ19: =IFERROR(INDEX(Tables!$AQ$2:$AQ$59,MATCH($C$9,Tables!$C$2:$C$59,0)),0) -> 0
A20: Masa, lunar month (Vedic) | D20: =IFERROR(INDEX(Tables!$D$2:$D$59,MATCH($C$10,Tables!$C$2:$C$59,0)),0) -> 0 | E20: =IFERROR(INDEX(Tables!$E$2:$E$59,MATCH($C$10,Tables!$C$2:$C$59,0)),0) -> 0 | F20: =IFERROR(INDEX(Tables!$F$2:$F$59,MATCH($C$10,Tables!$C$2:$C$59,0)),0) -> 0 | G20: =IFERROR(INDEX(Tables!$G$2:$G$59,MATCH($C$10,Tables!$C$2:$C$59,0)),0) -> 0 | H20: =IFERROR(INDEX(Tables!$H$2:$H$59,MATCH($C$10,Tables!$C$2:$C$59,0)),0) -> 0 | I20: =IFERROR(INDEX(Tables!$I$2:$I$59,MATCH($C$10,Tables!$C$2:$C$59,0)),0) -> 0 | J20: =IFERROR(INDEX(Tables!$J$2:$J$59,MATCH($C$10,Tables!$C$2:$C$59,0)),0) -> 0 | K20: =IFERROR(INDEX(Tables!$K$2:$K$59,MATCH($C$10,Tables!$C$2:$C$59,0)),0) -> 0 | L20: =IFERROR(INDEX(Tables!$L$2:$L$59,MATCH($C$10,Tables!$C$2:$C$59,0)),0) -> 0 | M20: =IFERROR(INDEX(Tables!$M$2:$M$59,MATCH($C$10,Tables!$C$2:$C$59,0)),0) -> 0 | N20: =IFERROR(INDEX(Tables!$N$2:$N$59,MATCH($C$10,Tables!$C$2:$C$59,0)),0) -> 0 | O20: =IFERROR(INDEX(Tables!$O$2:$O$59,MATCH($C$10,Tables!$C$2:$C$59,0)),0) -> 0 | P20: =IFERROR(INDEX(Tables!$P$2:$P$59,MATCH($C$10,Tables!$C$2:$C$59,0)),0) -> 0 | Q20: =IFERROR(INDEX(Tables!$Q$2:$Q$59,MATCH($C$10,Tables!$C$2:$C$59,0)),0) -> 0 | R20: =IFERROR(INDEX(Tables!$R$2:$R$59,MATCH($C$10,Tables!$C$2:$C$59,0)),0) -> 0 | S20: =IFERROR(INDEX(Tables!$S$2:$S$59,MATCH($C$10,Tables!$C$2:$C$59,0)),0) -> 0 | T20: =IFERROR(INDEX(Tables!$T$2:$T$59,MATCH($C$10,Tables!$C$2:$C$59,0)),0) -> 0 | U20: =IFERROR(INDEX(Tables!$U$2:$U$59,MATCH($C$10,Tables!$C$2:$C$59,0)),0) -> 0 | V20: =IFERROR(INDEX(Tables!$V$2:$V$59,MATCH($C$10,Tables!$C$2:$C$59,0)),0) -> 0 | W20: =IFERROR(INDEX(Tables!$W$2:$W$59,MATCH($C$10,Tables!$C$2:$C$59,0)),0) -> 0 | X20: =IFERROR(INDEX(Tables!$X$2:$X$59,MATCH($C$10,Tables!$C$2:$C$59,0)),0) -> 0 | Y20: =IFERROR(INDEX(Tables!$Y$2:$Y$59,MATCH($C$10,Tables!$C$2:$C$59,0)),0) -> 0 | Z20: =IFERROR(INDEX(Tables!$Z$2:$Z$59,MATCH($C$10,Tables!$C$2:$C$59,0)),0) -> 0 | AA20: =IFERROR(INDEX(Tables!$AA$2:$AA$59,MATCH($C$10,Tables!$C$2:$C$59,0)),0) -> 0 | AB20: =IFERROR(INDEX(Tables!$AB$2:$AB$59,MATCH($C$10,Tables!$C$2:$C$59,0)),0) -> 0 | AC20: =IFERROR(INDEX(Tables!$AC$2:$AC$59,MATCH($C$10,Tables!$C$2:$C$59,0)),0) -> 0 | AD20: =IFERROR(INDEX(Tables!$AD$2:$AD$59,MATCH($C$10,Tables!$C$2:$C$59,0)),0) -> 0 | AE20: =IFERROR(INDEX(Tables!$AE$2:$AE$59,MATCH($C$10,Tables!$C$2:$C$59,0)),0) -> 0 | AF20: =IFERROR(INDEX(Tables!$AF$2:$AF$59,MATCH($C$10,Tables!$C$2:$C$59,0)),0) -> 0 | AG20: =IFERROR(INDEX(Tables!$AG$2:$AG$59,MATCH($C$10,Tables!$C$2:$C$59,0)),0) -> 0 | AH20: =IFERROR(INDEX(Tables!$AH$2:$AH$59,MATCH($C$10,Tables!$C$2:$C$59,0)),0) -> 0 | AI20: =IFERROR(INDEX(Tables!$AI$2:$AI$59,MATCH($C$10,Tables!$C$2:$C$59,0)),0) -> 0 | AJ20: =IFERROR(INDEX(Tables!$AJ$2:$AJ$59,MATCH($C$10,Tables!$C$2:$C$59,0)),0) -> 0 | AK20: =IFERROR(INDEX(Tables!$AK$2:$AK$59,MATCH($C$10,Tables!$C$2:$C$59,0)),0) -> 0 | AL20: =IFERROR(INDEX(Tables!$AL$2:$AL$59,MATCH($C$10,Tables!$C$2:$C$59,0)),0) -> 0 | AM20: =IFERROR(INDEX(Tables!$AM$2:$AM$59,MATCH($C$10,Tables!$C$2:$C$59,0)),0) -> 0 | AN20: =IFERROR(INDEX(Tables!$AN$2:$AN$59,MATCH($C$10,Tables!$C$2:$C$59,0)),0) -> 0 | AO20: =IFERROR(INDEX(Tables!$AO$2:$AO$59,MATCH($C$10,Tables!$C$2:$C$59,0)),0) -> 0 | AP20: =IFERROR(INDEX(Tables!$AP$2:$AP$59,MATCH($C$10,Tables!$C$2:$C$59,0)),0) -> 0 | AQ20: =IFERROR(INDEX(Tables!$AQ$2:$AQ$59,MATCH($C$10,Tables!$C$2:$C$59,0)),0) -> 0
A21: Chinese year heavenly stem | D21: =IFERROR(INDEX(Tables!$D$2:$D$59,MATCH($C$11,Tables!$C$2:$C$59,0)),0) -> 0 | E21: =IFERROR(INDEX(Tables!$E$2:$E$59,MATCH($C$11,Tables!$C$2:$C$59,0)),0) -> 0 | F21: =IFERROR(INDEX(Tables!$F$2:$F$59,MATCH($C$11,Tables!$C$2:$C$59,0)),0) -> 0 | G21: =IFERROR(INDEX(Tables!$G$2:$G$59,MATCH($C$11,Tables!$C$2:$C$59,0)),0) -> 0 | H21: =IFERROR(INDEX(Tables!$H$2:$H$59,MATCH($C$11,Tables!$C$2:$C$59,0)),0) -> 0 | I21: =IFERROR(INDEX(Tables!$I$2:$I$59,MATCH($C$11,Tables!$C$2:$C$59,0)),0) -> 0 | J21: =IFERROR(INDEX(Tables!$J$2:$J$59,MATCH($C$11,Tables!$C$2:$C$59,0)),0) -> 0 | K21: =IFERROR(INDEX(Tables!$K$2:$K$59,MATCH($C$11,Tables!$C$2:$C$59,0)),0) -> 0 | L21: =IFERROR(INDEX(Tables!$L$2:$L$59,MATCH($C$11,Tables!$C$2:$C$59,0)),0) -> 0 | M21: =IFERROR(INDEX(Tables!$M$2:$M$59,MATCH($C$11,Tables!$C$2:$C$59,0)),0) -> 0 | N21: =IFERROR(INDEX(Tables!$N$2:$N$59,MATCH($C$11,Tables!$C$2:$C$59,0)),0) -> 0 | O21: =IFERROR(INDEX(Tables!$O$2:$O$59,MATCH($C$11,Tables!$C$2:$C$59,0)),0) -> 0 | P21: =IFERROR(INDEX(Tables!$P$2:$P$59,MATCH($C$11,Tables!$C$2:$C$59,0)),0) -> 0 | Q21: =IFERROR(INDEX(Tables!$Q$2:$Q$59,MATCH($C$11,Tables!$C$2:$C$59,0)),0) -> 0 | R21: =IFERROR(INDEX(Tables!$R$2:$R$59,MATCH($C$11,Tables!$C$2:$C$59,0)),0) -> 0 | S21: =IFERROR(INDEX(Tables!$S$2:$S$59,MATCH($C$11,Tables!$C$2:$C$59,0)),0) -> 0 | T21: =IFERROR(INDEX(Tables!$T$2:$T$59,MATCH($C$11,Tables!$C$2:$C$59,0)),0) -> 0 | U21: =IFERROR(INDEX(Tables!$U$2:$U$59,MATCH($C$11,Tables!$C$2:$C$59,0)),0) -> 0 | V21: =IFERROR(INDEX(Tables!$V$2:$V$59,MATCH($C$11,Tables!$C$2:$C$59,0)),0) -> 0 | W21: =IFERROR(INDEX(Tables!$W$2:$W$59,MATCH($C$11,Tables!$C$2:$C$59,0)),0) -> 0 | X21: =IFERROR(INDEX(Tables!$X$2:$X$59,MATCH($C$11,Tables!$C$2:$C$59,0)),0) -> 0 | Y21: =IFERROR(INDEX(Tables!$Y$2:$Y$59,MATCH($C$11,Tables!$C$2:$C$59,0)),0) -> 0 | Z21: =IFERROR(INDEX(Tables!$Z$2:$Z$59,MATCH($C$11,Tables!$C$2:$C$59,0)),0) -> 0 | AA21: =IFERROR(INDEX(Tables!$AA$2:$AA$59,MATCH($C$11,Tables!$C$2:$C$59,0)),0) -> 0 | AB21: =IFERROR(INDEX(Tables!$AB$2:$AB$59,MATCH($C$11,Tables!$C$2:$C$59,0)),0) -> 0 | AC21: =IFERROR(INDEX(Tables!$AC$2:$AC$59,MATCH($C$11,Tables!$C$2:$C$59,0)),0) -> 0 | AD21: =IFERROR(INDEX(Tables!$AD$2:$AD$59,MATCH($C$11,Tables!$C$2:$C$59,0)),0) -> 0 | AE21: =IFERROR(INDEX(Tables!$AE$2:$AE$59,MATCH($C$11,Tables!$C$2:$C$59,0)),0) -> 0 | AF21: =IFERROR(INDEX(Tables!$AF$2:$AF$59,MATCH($C$11,Tables!$C$2:$C$59,0)),0) -> 0 | AG21: =IFERROR(INDEX(Tables!$AG$2:$AG$59,MATCH($C$11,Tables!$C$2:$C$59,0)),0) -> 0 | AH21: =IFERROR(INDEX(Tables!$AH$2:$AH$59,MATCH($C$11,Tables!$C$2:$C$59,0)),0) -> 0 | AI21: =IFERROR(INDEX(Tables!$AI$2:$AI$59,MATCH($C$11,Tables!$C$2:$C$59,0)),0) -> 0 | AJ21: =IFERROR(INDEX(Tables!$AJ$2:$AJ$59,MATCH($C$11,Tables!$C$2:$C$59,0)),0) -> 0 | AK21: =IFERROR(INDEX(Tables!$AK$2:$AK$59,MATCH($C$11,Tables!$C$2:$C$59,0)),0) -> 0 | AL21: =IFERROR(INDEX(Tables!$AL$2:$AL$59,MATCH($C$11,Tables!$C$2:$C$59,0)),0) -> 0 | AM21: =IFERROR(INDEX(Tables!$AM$2:$AM$59,MATCH($C$11,Tables!$C$2:$C$59,0)),0) -> 0 | AN21: =IFERROR(INDEX(Tables!$AN$2:$AN$59,MATCH($C$11,Tables!$C$2:$C$59,0)),0) -> 0 | AO21: =IFERROR(INDEX(Tables!$AO$2:$AO$59,MATCH($C$11,Tables!$C$2:$C$59,0)),0) -> 0 | AP21: =IFERROR(INDEX(Tables!$AP$2:$AP$59,MATCH($C$11,Tables!$C$2:$C$59,0)),0) -> 0 | AQ21: =IFERROR(INDEX(Tables!$AQ$2:$AQ$59,MATCH($C$11,Tables!$C$2:$C$59,0)),0) -> 0
A22: Chinese lunar day | D22: =IFERROR(INDEX(Tables!$D$2:$D$59,MATCH($C$12,Tables!$C$2:$C$59,0)),0) -> 0 | E22: =IFERROR(INDEX(Tables!$E$2:$E$59,MATCH($C$12,Tables!$C$2:$C$59,0)),0) -> 0 | F22: =IFERROR(INDEX(Tables!$F$2:$F$59,MATCH($C$12,Tables!$C$2:$C$59,0)),0) -> 0 | G22: =IFERROR(INDEX(Tables!$G$2:$G$59,MATCH($C$12,Tables!$C$2:$C$59,0)),0) -> 0 | H22: =IFERROR(INDEX(Tables!$H$2:$H$59,MATCH($C$12,Tables!$C$2:$C$59,0)),0) -> 0 | I22: =IFERROR(INDEX(Tables!$I$2:$I$59,MATCH($C$12,Tables!$C$2:$C$59,0)),0) -> 0 | J22: =IFERROR(INDEX(Tables!$J$2:$J$59,MATCH($C$12,Tables!$C$2:$C$59,0)),0) -> 0 | K22: =IFERROR(INDEX(Tables!$K$2:$K$59,MATCH($C$12,Tables!$C$2:$C$59,0)),0) -> 0 | L22: =IFERROR(INDEX(Tables!$L$2:$L$59,MATCH($C$12,Tables!$C$2:$C$59,0)),0) -> 0 | M22: =IFERROR(INDEX(Tables!$M$2:$M$59,MATCH($C$12,Tables!$C$2:$C$59,0)),0) -> 0 | N22: =IFERROR(INDEX(Tables!$N$2:$N$59,MATCH($C$12,Tables!$C$2:$C$59,0)),0) -> 0 | O22: =IFERROR(INDEX(Tables!$O$2:$O$59,MATCH($C$12,Tables!$C$2:$C$59,0)),0) -> 0 | P22: =IFERROR(INDEX(Tables!$P$2:$P$59,MATCH($C$12,Tables!$C$2:$C$59,0)),0) -> 0 | Q22: =IFERROR(INDEX(Tables!$Q$2:$Q$59,MATCH($C$12,Tables!$C$2:$C$59,0)),0) -> 0 | R22: =IFERROR(INDEX(Tables!$R$2:$R$59,MATCH($C$12,Tables!$C$2:$C$59,0)),0) -> 0 | S22: =IFERROR(INDEX(Tables!$S$2:$S$59,MATCH($C$12,Tables!$C$2:$C$59,0)),0) -> 0 | T22: =IFERROR(INDEX(Tables!$T$2:$T$59,MATCH($C$12,Tables!$C$2:$C$59,0)),0) -> 0 | U22: =IFERROR(INDEX(Tables!$U$2:$U$59,MATCH($C$12,Tables!$C$2:$C$59,0)),0) -> 0 | V22: =IFERROR(INDEX(Tables!$V$2:$V$59,MATCH($C$12,Tables!$C$2:$C$59,0)),0) -> 0 | W22: =IFERROR(INDEX(Tables!$W$2:$W$59,MATCH($C$12,Tables!$C$2:$C$59,0)),0) -> 0 | X22: =IFERROR(INDEX(Tables!$X$2:$X$59,MATCH($C$12,Tables!$C$2:$C$59,0)),0) -> 0 | Y22: =IFERROR(INDEX(Tables!$Y$2:$Y$59,MATCH($C$12,Tables!$C$2:$C$59,0)),0) -> 0 | Z22: =IFERROR(INDEX(Tables!$Z$2:$Z$59,MATCH($C$12,Tables!$C$2:$C$59,0)),0) -> 0 | AA22: =IFERROR(INDEX(Tables!$AA$2:$AA$59,MATCH($C$12,Tables!$C$2:$C$59,0)),0) -> 0 | AB22: =IFERROR(INDEX(Tables!$AB$2:$AB$59,MATCH($C$12,Tables!$C$2:$C$59,0)),0) -> 0 | AC22: =IFERROR(INDEX(Tables!$AC$2:$AC$59,MATCH($C$12,Tables!$C$2:$C$59,0)),0) -> 0 | AD22: =IFERROR(INDEX(Tables!$AD$2:$AD$59,MATCH($C$12,Tables!$C$2:$C$59,0)),0) -> 0 | AE22: =IFERROR(INDEX(Tables!$AE$2:$AE$59,MATCH($C$12,Tables!$C$2:$C$59,0)),0) -> 0 | AF22: =IFERROR(INDEX(Tables!$AF$2:$AF$59,MATCH($C$12,Tables!$C$2:$C$59,0)),0) -> 0 | AG22: =IFERROR(INDEX(Tables!$AG$2:$AG$59,MATCH($C$12,Tables!$C$2:$C$59,0)),0) -> 0 | AH22: =IFERROR(INDEX(Tables!$AH$2:$AH$59,MATCH($C$12,Tables!$C$2:$C$59,0)),0) -> 0 | AI22: =IFERROR(INDEX(Tables!$AI$2:$AI$59,MATCH($C$12,Tables!$C$2:$C$59,0)),0) -> 0 | AJ22: =IFERROR(INDEX(Tables!$AJ$2:$AJ$59,MATCH($C$12,Tables!$C$2:$C$59,0)),0) -> 0 | AK22: =IFERROR(INDEX(Tables!$AK$2:$AK$59,MATCH($C$12,Tables!$C$2:$C$59,0)),0) -> 0 | AL22: =IFERROR(INDEX(Tables!$AL$2:$AL$59,MATCH($C$12,Tables!$C$2:$C$59,0)),0) -> 0 | AM22: =IFERROR(INDEX(Tables!$AM$2:$AM$59,MATCH($C$12,Tables!$C$2:$C$59,0)),0) -> 0 | AN22: =IFERROR(INDEX(Tables!$AN$2:$AN$59,MATCH($C$12,Tables!$C$2:$C$59,0)),0) -> 0 | AO22: =IFERROR(INDEX(Tables!$AO$2:$AO$59,MATCH($C$12,Tables!$C$2:$C$59,0)),0) -> 0 | AP22: =IFERROR(INDEX(Tables!$AP$2:$AP$59,MATCH($C$12,Tables!$C$2:$C$59,0)),0) -> 0 | AQ22: =IFERROR(INDEX(Tables!$AQ$2:$AQ$59,MATCH($C$12,Tables!$C$2:$C$59,0)),0) -> 0
A24: Step 3: total points = sum of the rows above (best digit per position highlighted)
A25: Position | B25: 0 | C25: 1 | D25: 2 | E25: 3 | F25: 4 | G25: 5 | H25: 6 | I25: 7 | J25: 8 | K25: 9 | M25: Best digit | N25: 2nd best | AJ25: Tie-break helper (points + digit/1,000,000)
A26: Position 1 | B26: =SUM(D17:D22) -> 0 | C26: =SUM(E17:E22) -> -1 | D26: =SUM(F17:F22) -> 0 | E26: =SUM(G17:G22) -> 0 | F26: =SUM(H17:H22) -> 0 | G26: =SUM(I17:I22) -> 0 | H26: =SUM(J17:J22) -> 0 | I26: =SUM(K17:K22) -> 0 | ... K26: =SUM(M17:M22) -> 1 | M26: =MATCH(MAX($AJ26:$AS26),$AJ26:$AS26,0)-1 -> 9 | N26: =MATCH(LARGE($AJ26:$AS26,2),$AJ26:$AS26,0)-1 -> 8 | AJ26: =B26+0/1000000 -> 0 | AK26: =C26+1/1000000 -> -0.999999 | AL26: =D26+2/1000000 -> 2e-06 | AM26: =E26+3/1000000 -> 3e-06 | AN26: =F26+4/1000000 -> 4e-06 | AO26: =G26+5/1000000 -> 5e-06 | AP26: =H26+6/1000000 -> 6e-06 | AQ26: =I26+7/1000000 -> 7e-06 | AR26: =J26+8/1000000 -> 8e-06 | AS26: =K26+9/1000000 -> 1.000009
A27: Position 2 | B27: =SUM(N17:N22) -> 0 | C27: =SUM(O17:O22) -> 0 | D27: =SUM(P17:P22) -> 0 | E27: =SUM(Q17:Q22) -> 0 | F27: =SUM(R17:R22) -> 0 | G27: =SUM(S17:S22) -> 1 | H27: =SUM(T17:T22) -> 0 | I27: =SUM(U17:U22) -> 0 | ... K27: =SUM(W17:W22) -> 0 | M27: =MATCH(MAX($AJ27:$AS27),$AJ27:$AS27,0)-1 -> 5 | N27: =MATCH(LARGE($AJ27:$AS27,2),$AJ27:$AS27,0)-1 -> 9 | AJ27: =B27+0/1000000 -> 0 | AK27: =C27+1/1000000 -> 1e-06 | AL27: =D27+2/1000000 -> 2e-06 | AM27: =E27+3/1000000 -> 3e-06 | AN27: =F27+4/1000000 -> 4e-06 | AO27: =G27+5/1000000 -> 1.000005 | AP27: =H27+6/1000000 -> 6e-06 | AQ27: =I27+7/1000000 -> 7e-06 | AR27: =J27+8/1000000 -> 8e-06 | AS27: =K27+9/1000000 -> 9e-06
A28: Position 3 | B28: =SUM(X17:X22) -> 1 | C28: =SUM(Y17:Y22) -> 0 | D28: =SUM(Z17:Z22) -> 0 | E28: =SUM(AA17:AA22) -> 0 | F28: =SUM(AB17:AB22) -> 0 | G28: =SUM(AC17:AC22) -> 0 | H28: =SUM(AD17:AD22) -> 0 | I28: =SUM(AE17:AE22) -> 0 | ... K28: =SUM(AG17:AG22) -> 0 | M28: =MATCH(MAX($AJ28:$AS28),$AJ28:$AS28,0)-1 -> 0 | N28: =MATCH(LARGE($AJ28:$AS28,2),$AJ28:$AS28,0)-1 -> 9 | AJ28: =B28+0/1000000 -> 1 | AK28: =C28+1/1000000 -> 1e-06 | AL28: =D28+2/1000000 -> 2e-06 | AM28: =E28+3/1000000 -> 3e-06 | AN28: =F28+4/1000000 -> 4e-06 | AO28: =G28+5/1000000 -> 5e-06 | AP28: =H28+6/1000000 -> 6e-06 | AQ28: =I28+7/1000000 -> 7e-06 | AR28: =J28+8/1000000 -> 8e-06 | AS28: =K28+9/1000000 -> 9e-06
A29: Position 4 | B29: =SUM(AH17:AH22) -> 0 | C29: =SUM(AI17:AI22) -> 0 | D29: =SUM(AJ17:AJ22) -> 0 | E29: =SUM(AK17:AK22) -> 0 | F29: =SUM(AL17:AL22) -> 0 | G29: =SUM(AM17:AM22) -> 0 | H29: =SUM(AN17:AN22) -> 0 | I29: =SUM(AO17:AO22) -> 0 | ... K29: =SUM(AQ17:AQ22) -> 0 | M29: =MATCH(MAX($AJ29:$AS29),$AJ29:$AS29,0)-1 -> 9 | N29: =MATCH(LARGE($AJ29:$AS29,2),$AJ29:$AS29,0)-1 -> 7 | AJ29: =B29+0/1000000 -> 0 | AK29: =C29+1/1000000 -> 1e-06 | AL29: =D29+2/1000000 -> 2e-06 | AM29: =E29+3/1000000 -> 3e-06 | AN29: =F29+4/1000000 -> 4e-06 | AO29: =G29+5/1000000 -> 5e-06 | AP29: =H29+6/1000000 -> 6e-06 | AQ29: =I29+7/1000000 -> 7e-06 | AR29: =J29+8/1000000 -> -0.999992 | AS29: =K29+9/1000000 -> 9e-06
A31: Step 4: the 16 combinations of best / 2nd-best digits (0 = best, 1 = 2nd best)
A32: # | B32: Pos1 | C32: Pos2 | D32: Pos3 | E32: Pos4 | F32: Number | G32: Total points
A33: 1 | B33: =IF(0=0,$M$26,$N$26) -> 9 | C33: =IF(0=0,$M$27,$N$27) -> 5 | D33: =IF(0=0,$M$28,$N$28) -> 0 | E33: =IF(0=0,$M$29,$N$29) -> 9 | F33: =TEXT(B33*1000+C33*100+D33*10+E33,"0000") -> 9509 | G33: =INDEX($B$26:$K$26,B33+1)+INDEX($B$27:$K$27,C33+1)+INDEX($B$28:$K$28,D33+1)+INDEX($B$29:$K$29,E33+1)-0/1000000000-0/1000000000000 -> 3
A34: 2 | B34: =IF(0=0,$M$26,$N$26) -> 9 | C34: =IF(0=0,$M$27,$N$27) -> 5 | D34: =IF(0=0,$M$28,$N$28) -> 0 | E34: =IF(1=0,$M$29,$N$29) -> 7 | F34: =TEXT(B34*1000+C34*100+D34*10+E34,"0000") -> 9507 | G34: =INDEX($B$26:$K$26,B34+1)+INDEX($B$27:$K$27,C34+1)+INDEX($B$28:$K$28,D34+1)+INDEX($B$29:$K$29,E34+1)-1/1000000000-1/1000000000000 -> 3
A35: 3 | B35: =IF(0=0,$M$26,$N$26) -> 9 | C35: =IF(0=0,$M$27,$N$27) -> 5 | D35: =IF(1=0,$M$28,$N$28) -> 9 | E35: =IF(0=0,$M$29,$N$29) -> 9 | F35: =TEXT(B35*1000+C35*100+D35*10+E35,"0000") -> 9599 | G35: =INDEX($B$26:$K$26,B35+1)+INDEX($B$27:$K$27,C35+1)+INDEX($B$28:$K$28,D35+1)+INDEX($B$29:$K$29,E35+1)-1/1000000000-2/1000000000000 -> 2
A36: 4 | B36: =IF(0=0,$M$26,$N$26) -> 9 | C36: =IF(0=0,$M$27,$N$27) -> 5 | D36: =IF(1=0,$M$28,$N$28) -> 9 | E36: =IF(1=0,$M$29,$N$29) -> 7 | F36: =TEXT(B36*1000+C36*100+D36*10+E36,"0000") -> 9597 | G36: =INDEX($B$26:$K$26,B36+1)+INDEX($B$27:$K$27,C36+1)+INDEX($B$28:$K$28,D36+1)+INDEX($B$29:$K$29,E36+1)-2/1000000000-3/1000000000000 -> 2
A37: 5 | B37: =IF(0=0,$M$26,$N$26) -> 9 | C37: =IF(1=0,$M$27,$N$27) -> 9 | D37: =IF(0=0,$M$28,$N$28) -> 0 | E37: =IF(0=0,$M$29,$N$29) -> 9 | F37: =TEXT(B37*1000+C37*100+D37*10+E37,"0000") -> 9909 | G37: =INDEX($B$26:$K$26,B37+1)+INDEX($B$27:$K$27,C37+1)+INDEX($B$28:$K$28,D37+1)+INDEX($B$29:$K$29,E37+1)-1/1000000000-4/1000000000000 -> 2
A38: 6 | B38: =IF(0=0,$M$26,$N$26) -> 9 | C38: =IF(1=0,$M$27,$N$27) -> 9 | D38: =IF(0=0,$M$28,$N$28) -> 0 | E38: =IF(1=0,$M$29,$N$29) -> 7 | F38: =TEXT(B38*1000+C38*100+D38*10+E38,"0000") -> 9907 | G38: =INDEX($B$26:$K$26,B38+1)+INDEX($B$27:$K$27,C38+1)+INDEX($B$28:$K$28,D38+1)+INDEX($B$29:$K$29,E38+1)-2/1000000000-5/1000000000000 -> 2
A39: 7 | B39: =IF(0=0,$M$26,$N$26) -> 9 | C39: =IF(1=0,$M$27,$N$27) -> 9 | D39: =IF(1=0,$M$28,$N$28) -> 9 | E39: =IF(0=0,$M$29,$N$29) -> 9 | F39: =TEXT(B39*1000+C39*100+D39*10+E39,"0000") -> 9999 | G39: =INDEX($B$26:$K$26,B39+1)+INDEX($B$27:$K$27,C39+1)+INDEX($B$28:$K$28,D39+1)+INDEX($B$29:$K$29,E39+1)-2/1000000000-6/1000000000000 -> 1
A40: 8 | B40: =IF(0=0,$M$26,$N$26) -> 9 | C40: =IF(1=0,$M$27,$N$27) -> 9 | D40: =IF(1=0,$M$28,$N$28) -> 9 | E40: =IF(1=0,$M$29,$N$29) -> 7 | F40: =TEXT(B40*1000+C40*100+D40*10+E40,"0000") -> 9997 | G40: =INDEX($B$26:$K$26,B40+1)+INDEX($B$27:$K$27,C40+1)+INDEX($B$28:$K$28,D40+1)+INDEX($B$29:$K$29,E40+1)-3/1000000000-7/1000000000000 -> 1
A41: 9 | B41: =IF(1=0,$M$26,$N$26) -> 8 | C41: =IF(0=0,$M$27,$N$27) -> 5 | D41: =IF(0=0,$M$28,$N$28) -> 0 | E41: =IF(0=0,$M$29,$N$29) -> 9 | F41: =TEXT(B41*1000+C41*100+D41*10+E41,"0000") -> 8509 | G41: =INDEX($B$26:$K$26,B41+1)+INDEX($B$27:$K$27,C41+1)+INDEX($B$28:$K$28,D41+1)+INDEX($B$29:$K$29,E41+1)-1/1000000000-8/1000000000000 -> 2
A42: 10 | B42: =IF(1=0,$M$26,$N$26) -> 8 | C42: =IF(0=0,$M$27,$N$27) -> 5 | D42: =IF(0=0,$M$28,$N$28) -> 0 | E42: =IF(1=0,$M$29,$N$29) -> 7 | F42: =TEXT(B42*1000+C42*100+D42*10+E42,"0000") -> 8507 | G42: =INDEX($B$26:$K$26,B42+1)+INDEX($B$27:$K$27,C42+1)+INDEX($B$28:$K$28,D42+1)+INDEX($B$29:$K$29,E42+1)-2/1000000000-9/1000000000000 -> 2
A43: 11 | B43: =IF(1=0,$M$26,$N$26) -> 8 | C43: =IF(0=0,$M$27,$N$27) -> 5 | D43: =IF(1=0,$M$28,$N$28) -> 9 | E43: =IF(0=0,$M$29,$N$29) -> 9 | F43: =TEXT(B43*1000+C43*100+D43*10+E43,"0000") -> 8599 | G43: =INDEX($B$26:$K$26,B43+1)+INDEX($B$27:$K$27,C43+1)+INDEX($B$28:$K$28,D43+1)+INDEX($B$29:$K$29,E43+1)-2/1000000000-10/1000000000000 -> 1
A44: 12 | B44: =IF(1=0,$M$26,$N$26) -> 8 | C44: =IF(0=0,$M$27,$N$27) -> 5 | D44: =IF(1=0,$M$28,$N$28) -> 9 | E44: =IF(1=0,$M$29,$N$29) -> 7 | F44: =TEXT(B44*1000+C44*100+D44*10+E44,"0000") -> 8597 | G44: =INDEX($B$26:$K$26,B44+1)+INDEX($B$27:$K$27,C44+1)+INDEX($B$28:$K$28,D44+1)+INDEX($B$29:$K$29,E44+1)-3/1000000000-11/1000000000000 -> 1
...

Sheet How to use
A1: 4D manual formula (Vedic + Chinese parameters)
A3: How to use
A4: 1. Go to the Predict sheet and type the draw date in the yellow cell B3.
A5: 2. Read the top 5 numbers in the green box (column Q). The steps below the date show how they are worked out.
A6: 3. To do it fully by hand: look up the date's six parameter values (Calendar sheet), find each value's row in the Tables sheet, add the six rows together column by column, take the highest digit in each position.
A8: The formula
A9: Points(position p, digit d) = sum over the 6 parameters of TABLE[parameter value on the date][p][d]
A10: Number #1 = the digit with the most points in each of the 4 positions.
A11: Numbers #2-#5 = the next best of the 16 combinations of each position's best and 2nd-best digit, by total points.
A12: Parameters (chosen on 2012-2017 draws, then frozen): Chinese year yin/yang (weight 0.3), Venus combust (Vedic) (weight 0.3), Jupiter combust (Vedic) (weight 0.3), Masa, lunar month (Vedic) (weight 0.1), Chinese year heavenly stem (weight 0.1), Chinese lunar day (weight 0.1)
A14: How it performed on 2018-2026 draws it had not seen (tables rebuilt each January from earlier draws only)
A15: Top 5 numbers: 66 wins of any prize in 4186 draws vs 48.1 for random picks (1.373x, z = 2.58); Big Forecast return RM1.046 per RM1.
... A25: Legend: yellow = input cell; blue = fixed data (tables, calendar); green = looked up from another sheet; black = calculated.

Sheet Tables
A1: Parameter | B1: Value | C1: Key | D1: P1 d0 | E1: P1 d1 | F1: P1 d2 | G1: P1 d3 | H1: P1 d4 | I1: P1 d5 | J1: P1 d6 | K1: P1 d7 | L1: P1 d8 | M1: P1 d9 | N1: P2 d0 | O1: P2 d1 | P1: P2 d2 | Q1: P2 d3 | R1: P2 d4 | S1: P2 d5 | T1: P2 d6 | U1: P2 d7 | V1: P2 d8 | W1: P2 d9 | X1: P3 d0 | Y1: P3 d1 | Z1: P3 d2 | AA1: P3 d3 | AB1: P3 d4 | AC1: P3 d5 | AD1: P3 d6 | AE1: P3 d7 | AF1: P3 d8 | AG1: P3 d9 | AH1: P4 d0 | AI1: P4 d1 | AJ1: P4 d2 | AK1: P4 d3 | AL1: P4 d4 | AM1: P4 d5 | AN1: P4 d6 | AO1: P4 d7 | AP1: P4 d8 | AQ1: P4 d9
A2: year_yinyang | B2: Yang | C2: =A2&"|"&B2 -> year_yinyang|Yang | D2: 0 | E2: 0 | F2: 0 | G2: 0 | H2: 0 | I2: 0 | J2: 0 | K2: 0 | L2: 0 | M2: 0 | N2: 0 | O2: 0 | P2: 0 | Q2: 0 | R2: 0 | S2: 0 | T2: 0 | U2: 0 | V2: 0 | W2: 0 | X2: 0 | Y2: 0 | Z2: 0 | AA2: 0 | AB2: 0 | AC2: 0 | AD2: 0 | AE2: 0 | AF2: 0 | AG2: 0 | AH2: 0 | AI2: 0 | AJ2: 0 | AK2: 0 | AL2: 0 | AM2: 0 | AN2: 0 | AO2: 0 | AP2: 0 | AQ2: 0
A3: year_yinyang | B3: Yin | C3: =A3&"|"&B3 -> year_yinyang|Yin | D3: 0 | E3: 0 | F3: 0 | G3: 0 | H3: 0 | I3: 0 | J3: 0 | K3: 0 | L3: 0 | M3: 0 | N3: 0 | O3: 0 | P3: 0 | Q3: 0 | R3: 0 | S3: 0 | T3: 0 | U3: 0 | V3: 0 | W3: 0 | X3: 0 | Y3: 0 | Z3: 0 | AA3: 0 | AB3: 0 | AC3: 0 | AD3: 0 | AE3: 0 | AF3: 0 | AG3: 0 | AH3: 0 | AI3: 0 | AJ3: 0 | AK3: 0 | AL3: 0 | AM3: 0 | AN3: 0 | AO3: 0 | AP3: 0 | AQ3: 0
A4: venus_combust | B4: False | C4: =A4&"|"&B4 -> venus_combust|False | D4: 0 | E4: 0 | F4: 0 | G4: 0 | H4: 0 | I4: 0 | J4: 0 | K4: 0 | L4: 0 | M4: 0 | N4: 0 | O4: 0 | P4: 0 | Q4: 0 | R4: 0 | S4: 0 | T4: 0 | U4: 0 | V4: 0 | W4: 0 | X4: 0 | Y4: 0 | Z4: 0 | AA4: 0 | AB4: 0 | AC4: 0 | AD4: 0 | AE4: 0 | AF4: 0 | AG4: 0 | AH4: 0 | AI4: 0 | AJ4: 0 | AK4: 0 | AL4: 0 | AM4: 0 | AN4: 0 | AO4: 0 | AP4: 0 | AQ4: 0
A5: venus_combust | B5: True | C5: =A5&"|"&B5 -> venus_combust|True | D5: 0 | E5: -1 | F5: 0 | G5: 0 | H5: 0 | I5: 0 | J5: 0 | K5: 0 | L5: 0 | M5: 1 | N5: 0 | O5: 0 | P5: 0 | Q5: 0 | R5: 0 | S5: 1 | T5: 0 | U5: 0 | V5: 0 | W5: 0 | X5: 1 | Y5: 0 | Z5: 0 | AA5: 0 | AB5: 0 | AC5: 0 | AD5: 0 | AE5: 0 | AF5: 0 | AG5: 0 | AH5: 0 | AI5: 0 | AJ5: 0 | AK5: 0 | AL5: 0 | AM5: 0 | AN5: 0 | AO5: 0 | AP5: -1 | AQ5: 0
A6: jupiter_combust | B6: False | C6: =A6&"|"&B6 -> jupiter_combust|False | D6: 0 | E6: 0 | F6: 0 | G6: 0 | H6: 0 | I6: 0 | J6: 0 | K6: 0 | L6: 0 | M6: 0 | N6: 0 | O6: 0 | P6: 0 | Q6: 0 | R6: 0 | S6: 0 | T6: 0 | U6: 0 | V6: 0 | W6: 0 | X6: 0 | Y6: 0 | Z6: 0 | AA6: 0 | AB6: 0 | AC6: 0 | AD6: 0 | AE6: 0 | AF6: 0 | AG6: 0 | AH6: 0 | AI6: 0 | AJ6: 0 | AK6: 0 | AL6: 0 | AM6: 0 | AN6: 0 | AO6: 0 | AP6: 0 | AQ6: 0
A7: jupiter_combust | B7: True | C7: =A7&"|"&B7 -> jupiter_combust|True | D7: 1 | E7: 1 | F7: 1 | G7: 0 | H7: -1 | I7: 0 | J7: -1 | K7: 1 | L7: -1 | M7: 0 | N7: 1 | O7: 0 | P7: 0 | Q7: 0 | R7: 0 | S7: 0 | T7: 0 | U7: 0 | V7: 0 | W7: 1 | X7: 0 | Y7: 0 | Z7: 0 | AA7: 0 | AB7: 0 | AC7: -1 | AD7: 0 | AE7: 0 | AF7: 1 | AG7: 1 | AH7: 0 | AI7: -1 | AJ7: 0 | AK7: 0 | AL7: 0 | AM7: 0 | AN7: 0 | AO7: 0 | AP7: 0 | AQ7: 0
A8: masa | B8: Ashadha | C8: =A8&"|"&B8 -> masa|Ashadha | D8: 0 | E8: 0 | F8: 0 | G8: 0 | H8: 0 | I8: 0 | J8: 0 | K8: 0 | L8: 0 | M8: 0 | N8: 0 | O8: 0 | P8: 0 | Q8: 0 | R8: 0 | S8: 0 | T8: 0 | U8: 0 | V8: 0 | W8: 0 | X8: 0 | Y8: 0 | Z8: 0 | AA8: 0 | AB8: 0 | AC8: 0 | AD8: 0 | AE8: 0 | AF8: 0 | AG8: 0 | AH8: 0 | AI8: 0 | AJ8: 0 | AK8: 0 | AL8: 0 | AM8: 0 | AN8: 0 | AO8: 0 | AP8: 0 | AQ8: 0
A9: masa | B9: Ashvin | C9: =A9&"|"&B9 -> masa|Ashvin | D9: 0 | E9: 0 | F9: 0 | G9: 0 | H9: 0 | I9: 0 | J9: 0 | K9: 0 | L9: 0 | M9: 0 | N9: 0 | O9: 0 | P9: 0 | Q9: 0 | R9: 0 | S9: 0 | T9: 0 | U9: 0 | V9: 0 | W9: 0 | X9: 0 | Y9: 0 | Z9: 0 | AA9: 0 | AB9: 0 | AC9: 0 | AD9: 0 | AE9: 0 | AF9: 0 | AG9: 0 | AH9: 0 | AI9: 0 | AJ9: 0 | AK9: 0 | AL9: 0 | AM9: 0 | AN9: 0 | AO9: 0 | AP9: 0 | AQ9: 0
A10: masa | B10: Bhadrapada | C10: =A10&"|"&B10 -> masa|Bhadrapada | D10: 0 | E10: 0 | F10: 0 | G10: 0 | H10: 0 | I10: 0 | J10: 0 | K10: 0 | L10: 0 | M10: 0 | N10: 0 | O10: 0 | P10: 0 | Q10: 0 | R10: 0 | S10: 0 | T10: 0 | U10: 0 | V10: 0 | W10: 0 | X10: 0 | Y10: 0 | Z10: 0 | AA10: 0 | AB10: 0 | AC10: 0 | AD10: 0 | AE10: 0 | AF10: 0 | AG10: 0 | AH10: 0 | AI10: 0 | AJ10: 0 | AK10: 0 | AL10: 0 | AM10: 0 | AN10: 0 | AO10: 0 | AP10: 0 | AQ10: 0
A11: masa | B11: Chaitra | C11: =A11&"|"&B11 -> masa|Chaitra | D11: 0 | E11: 0 | F11: 0 | G11: 0 | H11: 0 | I11: 0 | J11: 0 | K11: 0 | L11: 0 | M11: 0 | N11: 0 | O11: 0 | P11: 0 | Q11: 0 | R11: 0 | S11: 0 | T11: 0 | U11: 0 | V11: 0 | W11: 0 | X11: 0 | Y11: 0 | Z11: 0 | AA11: 0 | AB11: 0 | AC11: 0 | AD11: 0 | AE11: 0 | AF11: 0 | AG11: 0 | AH11: 0 | AI11: 0 | AJ11: 0 | AK11: 0 | AL11: 0 | AM11: 0 | AN11: 0 | AO11: 0 | AP11: 0 | AQ11: 0
A12: masa | B12: Jyeshtha | C12: =A12&"|"&B12 -> masa|Jyeshtha | D12: 0 | E12: 0 | F12: 0 | G12: 0 | H12: 0 | I12: 0 | J12: 0 | K12: 0 | L12: 0 | M12: 0 | N12: 0 | O12: 0 | P12: 0 | Q12: 0 | R12: 0 | S12: 0 | T12: 0 | U12: 0 | V12: 0 | W12: 0 | X12: 0 | Y12: 0 | Z12: 0 | AA12: 0 | AB12: 0 | AC12: 0 | AD12: 0 | AE12: 0 | AF12: 0 | AG12: 0 | AH12: 0 | AI12: 0 | AJ12: 0 | AK12: 0 | AL12: 0 | AM12: 0 | AN12: 0 | AO12: 0 | AP12: 0 | AQ12: 0
A13: masa | B13: Kartika | C13: =A13&"|"&B13 -> masa|Kartika | D13: 0 | E13: 0 | F13: 0 | G13: 0 | H13: 0 | I13: 0 | J13: 0 | K13: 0 | L13: 0 | M13: 0 | N13: 0 | O13: 0 | P13: 0 | Q13: 0 | R13: 0 | S13: 0 | T13: 0 | U13: 0 | V13: 0 | W13: 0 | X13: 0 | Y13: 0 | Z13: 0 | AA13: 0 | AB13: 0 | AC13: 0 | AD13: 0 | AE13: 0 | AF13: 0 | AG13: 0 | AH13: 0 | AI13: 0 | AJ13: 0 | AK13: 0 | AL13: 0 | AM13: 0 | AN13: 0 | AO13: 0 | AP13: 0 | AQ13: 0
... A59: lunar_day | B59: 9 | C59: =A59&"|"&B59 -> lunar_day|9 | D59: 0 | E59: 0 | F59: 0 | G59: 0 | H59: 0 | I59: 0 | J59: 0 | K59: 0 | L59: 0 | M59: 0 | N59: 0 | O59: 0 | P59: 0 | Q59: 0 | R59: 0 | S59: 0 | T59: 0 | U59: 0 | V59: 0 | W59: 0 | X59: 0 | Y59: 0 | Z59: 0 | AA59: 0 | AB59: 0 | AC59: 0 | AD59: 0 | AE59: 0 | AF59: 0 | AG59: 0 | AH59: 0 | AI59: 0 | AJ59: 0 | AK59: 0 | AL59: 0 | AM59: 0 | AN59: 0 | AO59: 0 | AP59: 0 | AQ59: 0
A61: Points = round(100 x weight x log[ share of digit d at position p among past winners on dates with this value / its overall share ]), from all Magnum, Sports Toto and Da Ma Cai draws 1985 to 2026-10-14 (each number once per draw, smoothed with 50 pseudo-draws). Source: data/*.csv, analysis/manual_formula.py.

Sheet Calendar
A1: Date | B1: Weekday | C1: year_yinyang | D1: venus_combust | E1: jupiter_combust | F1: masa | G1: year_stem | H1: lunar_day
A2: 46310 | B2: Thu | C2: Yang | D2: False | E2: False | F2: Ashvin | G2: Bing | H2: 6
A3: 46311 | B3: Fri | C3: Yang | D3: False | E3: False | F3: Ashvin | G3: Bing | H3: 7
A4: 46312 | B4: Sat | C4: Yang | D4: False | E4: False | F4: Ashvin | G4: Bing | H4: 8
A5: 46313 | B5: Sun | C5: Yang | D5: True | E5: False | F5: Ashvin | G5: Bing | H5: 9
A6: 46314 | B6: Mon | C6: Yang | D6: True | E6: False | F6: Ashvin | G6: Bing | H6: 10
A7: 46315 | B7: Tue | C7: Yang | D7: True | E7: False | F7: Ashvin | G7: Bing | H7: 11
A8: 46316 | B8: Wed | C8: Yang | D8: True | E8: False | F8: Ashvin | G8: Bing | H8: 12
A9: 46317 | B9: Thu | C9: Yang | D9: True | E9: False | F9: Ashvin | G9: Bing | H9: 13
A10: 46318 | B10: Fri | C10: Yang | D10: True | E10: False | F10: Ashvin | G10: Bing | H10: 14
A11: 46319 | B11: Sat | C11: Yang | D11: True | E11: False | F11: Ashvin | G11: Bing | H11: 15
A12: 46320 | B12: Sun | C12: Yang | D12: True | E12: False | F12: Ashvin | G12: Bing | H12: 16
A13: 46321 | B13: Mon | C13: Yang | D13: True | E13: False | F13: Ashvin | G13: Bing | H13: 17
... A441: 46749 | B441: Tue | C441: Yin | D441: False | E441: False | F441: Pausha | G441: Ding | H441: 1
A443: Parameter values at 19:00 Malaysia time, computed by analysis/almanac.py (Meeus ephemeris, Lahiri ayanamsa, Chinese lunisolar calendar).
